Workbook
Name 분류목록: 분류체계!$A$2:$A$15

Sheet 문제은행
A1: 문항ID | B1: 민원 내용 | C1: 정답 분류 | D1: 표시 부서 | E1: 오답후보1 | F1: 오답후보2 | G1: 오답후보3 | H1: 해설 | I1: 난이도 | J1: 사업영역 | K1: 출처 | L1: 검수상태
A2: c001 | B2: 검색된 특허의 출원인 이름이 실제와 다르게 나옵니다. | C2: 데이터관리센터 | D2: =IFERROR(INDEX(분류체계!$D$2:$D$16,MATCH($C2,분류체계!$A$2:$A$16,0)),"") -> 분석플랫폼지원단 · 데이터관리실 | E2: 특허정보검색서비스(KIPRIS) | F2: 특허넷시스템 운영 | H2: 특허데이터 오류 판단·수정은 데이터관리센터가 담당합니다. | I2: 1 | J2: 지식재산정보 활용촉진 | K2: https://www.kipi.or.kr/EgovPageLink.do?link=/main/sub03/sub010201 | L2: 검수완료
A3: c002 | B3: 미국·유럽 특허 원문 데이터는 어디서 구축하나요? | C3: 데이터관리센터 | D3: =IFERROR(INDEX(분류체계!$D$2:$D$16,MATCH($C3,분류체계!$A$2:$A$16,0)),"") -> 분석플랫폼지원단 · 데이터관리실 | E3: 지식재산 정보화 국제협력 | F3: 특허정보활용서비스(KIPRISPlus) | H3: IP5 등 해외 주요기관 데이터를 수집해 구축합니다. | I3: 1 | J3: 지식재산정보 활용촉진 | K3: https://www.kipi.or.kr/EgovPageLink.do?link=/main/sub03/sub010201 | L3: 검수완료
A4: c003 | B4: 연구소인데 특허 원천데이터를 제공받고 싶습니다. | C4: 데이터관리센터 | D4: =IFERROR(INDEX(분류체계!$D$2:$D$16,MATCH($C4,분류체계!$A$2:$A$16,0)),"") -> 분석플랫폼지원단 · 데이터관리실 | E4: 특허정보활용서비스(KIPRISPlus) | F4: 지식재산 통계서비스 | H4: 국내외 기관 대상 특허원천데이터 제공은 데이터관리센터입니다. | I4: 2 | J4: 지식재산정보 활용촉진 | K4: https://www.kipi.or.kr/EgovPageLink.do?link=/main/sub03/sub010201 | L4: 검수완료
A5: c004 | B5: 특허 데이터를 국제표준 XML 서식으로 받고 싶습니다. | C5: 데이터관리센터 | D5: =IFERROR(INDEX(분류체계!$D$2:$D$16,MATCH($C5,분류체계!$A$2:$A$16,0)),"") -> 분석플랫폼지원단 · 데이터관리실 | E5: 특허정보활용서비스(KIPRISPlus) | F5: 특허넷시스템 운영 | H5: 지식재산처 데이터를 국제표준으로 가공·배포합니다. | I5: 2 | J5: 지식재산정보 활용촉진 | K5: https://www.kipi.or.kr/EgovPageLink.do?link=/main/sub03/sub010201 | L5: 검수완료
A6: c005 | B6: 같은 특허가 두 건으로 중복 등록돼 있습니다. | C6: 데이터관리센터 | D6: =IFERROR(INDEX(분류체계!$D$2:$D$16,MATCH($C6,분류체계!$A$2:$A$16,0)),"") -> 분석플랫폼지원단 · 데이터관리실 | E6: 특허넷시스템 운영 | F6: 특허정보검색서비스(KIPRIS) | H6: 데이터 오류 발생 방지와 정비가 데이터관리센터 업무입니다. | I6: 2 | J6: 지식재산정보 활용촉진 | K6: https://www.kipi.or.kr/EgovPageLink.do?link=/main/sub03/sub010201 | L6: 검수완료
A7: c006 | B7: IPC 분류 코드가 공보와 검색 결과에서 서로 다릅니다. | C7: 데이터관리센터 | D7: =IFERROR(INDEX(분류체계!$D$2:$D$16,MATCH($C7,분류체계!$A$2:$A$16,0)),"") -> 분석플랫폼지원단 · 데이터관리실 | E7: 특허정보검색서비스(KIPRIS) | F7: 지식재산 정보화 R&D | G7: 특허넷시스템 운영 | H7: 데이터 정합성 검증과 오류 수정은 데이터관리센터 소관입니다. | I7: 3 | J7: 지식재산정보 활용촉진 | K7: https://www.kipi.or.kr/EgovPageLink.do?link=/main/sub03/sub010201 | L7: 검수완료
A8: c007 | B8: 심사에 쓰이는 해외 선행문헌 DB는 누가 관리하나요? | C8: 데이터관리센터 | D8: =IFERROR(INDEX(분류체계!$D$2:$D$16,MATCH($C8,분류체계!$A$2:$A$16,0)),"") -> 분석플랫폼지원단 · 데이터관리실 | E8: 특허넷시스템 운영 | F8: 지식재산 정보화 국제협력 | G8: 한국특허영문초록(KPA) | H8: 심사·심판 지원을 위한 국내외 IP 데이터 구축을 담당합니다. | I8: 3 | J8: 지식재산정보 활용촉진 | K8: https://www.kipi.or.kr/EgovPageLink.do?link=/main/sub03/sub010201 | L8: 검수완료
A9: c008 | B9: 데이터 품질 지표를 공개된 자료로 확인할 수 있나요? | C9: 데이터관리센터 | D9: =IFERROR(INDEX(분류체계!$D$2:$D$16,MATCH($C9,분류체계!$A$2:$A$16,0)),"") -> 분석플랫폼지원단 · 데이터관리실 | E9: 지식재산 통계서비스 | F9: 특허정보활용서비스(KIPRISPlus) | H9: 특허데이터 품질관리 업무는 데이터관리센터가 수행합니다. | I9: 3 | J9: 지식재산정보 활용촉진 | K9: https://www.kipi.or.kr/EgovPageLink.do?link=/main/sub03/sub010201 | L9: 검수완료
A10: c009 | B10: 특허를 무료로 검색할 수 있는 사이트가 있나요? | C10: 특허정보검색서비스(KIPRIS) | D10: =IFERROR(INDEX(분류체계!$D$2:$D$16,MATCH($C10,분류체계!$A$2:$A$16,0)),"") -> 정보활용본부 · IP정보확산실 | E10: 특허정보활용서비스(KIPRISPlus) | F10: 특허고객 상담서비스 | H10: KIPRIS는 누구나 무료로 쓰는 대국민 특허정보 검색서비스입니다. | I10: 1 | J10: 지식재산정보 활용촉진 | K10: https://www.kipi.or.kr/EgovPageLink.do?link=/main/sub03/sub0101 | L10: 검수완료
A11: c010 | B11: 특허 검색이 처음인데 쉬운 검색 방법이 있나요? | C11: 특허정보검색서비스(KIPRIS) | D11: =IFERROR(INDEX(분류체계!$D$2:$D$16,MATCH($C11,분류체계!$A$2:$A$16,0)),"") -> 정보활용본부 · IP정보확산실 | E11: 특허고객 상담서비스 | F11: 지식재산 기술지원 | H11: 일반·스마트·초보자·문장검색 등 수준별 검색을 제공합니다. | I11: 1 | J11: 지식재산정보 활용촉진 | K11: https://www.kipi.or.kr/EgovPageLink.do?link=/main/sub03/sub0101 | L11: 검수완료
A12: c011 | B12: 관심 있는 기술의 신규 특허를 메일로 받고 싶습니다. | C12: 특허정보검색서비스(KIPRIS) | D12: =IFERROR(INDEX(분류체계!$D$2:$D$16,MATCH($C12,분류체계!$A$2:$A$16,0)),"") -> 정보활용본부 · IP정보확산실 | E12: 특허정보활용서비스(KIPRISPlus) | F12: 지식재산 통계서비스 | H12: 검색식 메일링으로 신규 공보를 메일로 받습니다. | I12: 2 | J12: 지식재산정보 활용촉진 | K12: https://www.kipi.or.kr/EgovPageLink.do?link=/main/sub03/sub0101 | L12: 검수완료
A13: c012 | B13: 검색 결과에 심사 진행 이력도 같이 나오나요? | C13: 특허정보검색서비스(KIPRIS) | D13: =IFERROR(INDEX(분류체계!$D$2:$D$16,MATCH($C13,분류체계!$A$2:$A$16,0)),"") -> 정보활용본부 · IP정보확산실 | E13: 특허넷시스템 운영 | F13: 데이터관리센터 | H13: KIPRIS는 심사행정정보를 포함한 다양한 IP 정보를 제공합니다. | I13: 2 | J13: 지식재산정보 활용촉진 | K13: https://www.kipi.or.kr/EgovPageLink.do?link=/main/sub03/sub0101 | L13: 검수완료
A14: c013 | B14: 우리 회사 홈페이지에 특허 검색 기능을 넣고 싶습니다. | C14: 특허정보검색서비스(KIPRIS) | D14: =IFERROR(INDEX(분류체계!$D$2:$D$16,MATCH($C14,분류체계!$A$2:$A$16,0)),"") -> 정보활용본부 · IP정보확산실 | E14: 특허정보활용서비스(KIPRISPlus) | F14: 지식재산 정보화 R&D | H14: KIPRIS 연계로 외부 사이트에 검색을 제공합니다. | I14: 3 | J14: 지식재산정보 활용촉진 | K14: https://www.kipi.or.kr/EgovPageLink.do?link=/main/sub03/sub0101 | L14: 검수완료
A15: c014 | B15: 문장을 그대로 넣어 비슷한 특허를 찾을 수 있나요? | C15: 특허정보검색서비스(KIPRIS) | D15: =IFERROR(INDEX(분류체계!$D$2:$D$16,MATCH($C15,분류체계!$A$2:$A$16,0)),"") -> 정보활용본부 · IP정보확산실 | E15: 지식재산 정보화 R&D | F15: 데이터관리센터 | H15: 문장검색 기능을 제공합니다. | I15: 2 | J15: 지식재산정보 활용촉진 | K15: https://www.kipi.or.kr/EgovPageLink.do?link=/main/sub03/sub0101 | L15: 검수완료
A16: c015 | B16: 상표와 디자인도 같은 곳에서 검색되나요? | C16: 특허정보검색서비스(KIPRIS) | D16: =IFERROR(INDEX(분류체계!$D$2:$D$16,MATCH($C16,분류체계!$A$2:$A$16,0)),"") -> 정보활용본부 · IP정보확산실 | E16: 데이터관리센터 | F16: 특허고객 상담서비스 | H16: KIPRIS는 국내외 지식재산권 정보를 통합 검색합니다. | I16: 1 | J16: 지식재산정보 활용촉진 | K16: https://www.kipi.or.kr/EgovPageLink.do?link=/main/sub03/sub0101 | L16: 검수완료
A17: c016 | B17: 검색식을 어떻게 짜야 할지 모르겠습니다. | C17: 특허정보검색서비스(KIPRIS) | D17: =IFERROR(INDEX(분류체계!$D$2:$D$16,MATCH($C17,분류체계!$A$2:$A$16,0)),"") -> 정보활용본부 · IP정보확산실 | E17: 특허고객 상담서비스 | F17: 지식재산 기술지원 | H17: 추천검색식·검색식 저장 등 보조 기능을 제공합니다. | I17: 2 | J17: 지식재산정보 활용촉진 | K17: https://www.kipi.or.kr/EgovPageLink.do?link=/main/sub03/sub0101 | L17: 검수완료
A18: c017 | B18: 논문 같은 비특허 자료도 검색되나요? | C18: 특허정보검색서비스(KIPRIS) | D18: =IFERROR(INDEX(분류체계!$D$2:$D$16,MATCH($C18,분류체계!$A$2:$A$16,0)),"") -> 정보활용본부 · IP정보확산실 | E18: 데이터관리센터 | F18: 지식재산 통계서비스 | H18: 비특허 정보(NPL)도 검색 대상에 포함됩니다. | I18: 2 | J18: 지식재산정보 활용촉진 | K18: 브로슈어 p.07-08 / 미확인: 현행 KIPRIS 페이지에 비특허문헌(NPL) 검색 기능 언급 없음 | L18: 보류
A19: c018 | B19: 무료 특허 검색 사이트가 열리지 않습니다. | C19: 특허정보검색서비스(KIPRIS) | D19: =IFERROR(INDEX(분류체계!$D$2:$D$16,MATCH($C19,분류체계!$A$2:$A$16,0)),"") -> 정보활용본부 · IP정보확산실 | E19: IP정보통합센터 | F19: 특허넷시스템 운영 | H19: 대국민 검색서비스 KIPRIS의 운영 주체가 대응합니다. | I19: 1 | J19: 지식재산정보 활용촉진 | K19: https://www.kipi.or.kr/EgovPageLink.do?link=/main/sub03/sub0101 | L19: 검수완료
A20: c019 | B20: 종이로 낸 출원서류가 시스템에 안 보입니다. | C20: 특허문서전자화센터 | D20: =IFERROR(INDEX(분류체계!$D$2:$D$16,MATCH($C20,분류체계!$A$2:$A$16,0)),"") -> 지능정보화센터 · 지능정보데이터실 | E20: 특허넷시스템 운영 | F20: 특허고객 상담서비스 | H20: 지식재산처 제출 서면서류의 전자화를 담당합니다. | I20: 1 | J20: 지식재산정보 활용촉진 | K20: https://www.kipi.or.kr/EgovPageLink.do?link=/main/sub03/sub010202 | L20: 검수완료
... A26: c025 | B26: 제출한 서류가 시스템에 오타로 입력됐습니다. | C26: 특허문서전자화센터 | D26: =IFERROR(INDEX(분류체계!$D$2:$D$16,MATCH($C26,분류체계!$A$2:$A$16,0)),"") -> 지능정보화센터 · 지능정보데이터실 | E26: 데이터관리센터 | F26: 특허넷시스템 운영 | H26: 전자화 데이터의 교정 및 검증을 수행합니다. | I26: 3 | J26: 지식재산정보 활용촉진 | K26: https://www.kipi.or.kr/EgovPageLink.do?link=/main/sub03/sub010202 | L26: 검수완료
A27: c026 | B27: 장애인 단체인데 특허정보 검색 교육을 요청합니다. | C27: 특허문서전자화센터 | D27: =IFERROR(INDEX(분류체계!$D$2:$D$16,MATCH($C27,분류체계!$A$2:$A$16,0)),"") -> 지능정보화센터 · 지능정보데이터실 | E27: 지식재산 기술지원 | F27: 특허고객 상담서비스 | G27: 특허정보검색서비스(KIPRIS) | H27: 정보화 취약계층 대상 특허정보 검색 교육을 운영합니다. | I27: 3 | J27: 지식재산정보 활용촉진 | K27: https://www.kipi.or.kr/EgovPageLink.do?link=/main/sub03/sub010202 | L27: 검수완료
A28: c027 | B28: 한국 특허를 영어 요약으로 볼 수 있나요? | C28: 한국특허영문초록(KPA) | D28: =IFERROR(INDEX(분류체계!$D$2:$D$16,MATCH($C28,분류체계!$A$2:$A$16,0)),"") -> 정보활용본부 · IP정보가공실 | E28: PCT 국제출원문서 번역 | F28: 특허정보검색서비스(KIPRIS) | H28: KPA는 한국특허공보의 영문요약서입니다. | I28: 1 | J28: 지식재산정보 활용촉진 | K28: https://www.kipi.or.kr/EgovPageLink.do?link=/main/sub03/sub010203 | L28: 검수완료
A29: c028 | B29: 해외 특허청도 우리 특허를 영어로 볼 수 있나요? | C29: 한국특허영문초록(KPA) | D29: =IFERROR(INDEX(분류체계!$D$2:$D$16,MATCH($C29,분류체계!$A$2:$A$16,0)),"") -> 정보활용본부 · IP정보가공실 | E29: 지식재산 정보화 국제협력 | F29: PCT 국제출원문서 번역 | H29: 해외 특허청·유관기관에 무상 보급하고 있습니다. | I29: 2 | J29: 지식재산정보 활용촉진 | K29: https://www.kipi.or.kr/EgovPageLink.do?link=/main/sub03/sub010203 | L29: 검수완료
A30: c029 | B30: 한국 특허의 영어 자료는 유료인가요? | C30: 한국특허영문초록(KPA) | D30: =IFERROR(INDEX(분류체계!$D$2:$D$16,MATCH($C30,분류체계!$A$2:$A$16,0)),"") -> 정보활용본부 · IP정보가공실 | E30: PCT 국제출원문서 번역 | F30: 특허정보활용서비스(KIPRISPlus) | H30: KPA는 KIPRIS를 통해 무료로 검색할 수 있습니다. | I30: 2 | J30: 지식재산정보 활용촉진 | K30: https://www.kipi.or.kr/EgovPageLink.do?link=/main/sub03/sub010203 | L30: 검수완료
A31: c030 | B31: 도면 안의 한글 표기는 영어로 어떻게 되나요? | C31: 한국특허영문초록(KPA) | D31: =IFERROR(INDEX(분류체계!$D$2:$D$16,MATCH($C31,분류체계!$A$2:$A$16,0)),"") -> 정보활용본부 · IP정보가공실 | E31: 특허문서전자화센터 | F31: PCT 국제출원문서 번역 | G31: 데이터관리센터 | H31: 대표도에 기재된 국문표기를 영문으로 번역합니다. | I31: 3 | J31: 지식재산정보 활용촉진 | K31: https://www.kipi.or.kr/EgovPageLink.do?link=/main/sub03/sub010203 | L31: 검수완료
A32: c031 | B32: 우리 특허가 해외에서 보호받게 하려면 영문 자료가 필요합니다. | C32: 한국특허영문초록(KPA) | D32: =IFERROR(INDEX(분류체계!$D$2:$D$16,MATCH($C32,분류체계!$A$2:$A$16,0)),"") -> 정보활용본부 · IP정보가공실 | E32: PCT 국제출원문서 번역 | F32: 지식재산 정보화 국제협력 | H32: KPA는 국내 특허기술의 해외 보호 강화를 목적으로 발간됩니다. | I32: 2 | J32: 지식재산정보 활용촉진 | K32: https://www.kipi.or.kr/EgovPageLink.do?link=/main/sub03/sub010203 | L32: 검수완료
A33: c032 | B33: 영어로 된 요약서의 출원번호가 틀렸습니다. | C33: 한국특허영문초록(KPA) | D33: =IFERROR(INDEX(분류체계!$D$2:$D$16,MATCH($C33,분류체계!$A$2:$A$16,0)),"") -> 정보활용본부 · IP정보가공실 | E33: 데이터관리센터 | F33: PCT 국제출원문서 번역 | G33: 특허문서전자화센터 | H33: KPA 제작 과정의 서지정보 제작·검수를 담당합니다. | I33: 3 | J33: 지식재산정보 활용촉진 | K33: https://www.kipi.or.kr/EgovPageLink.do?link=/main/sub03/sub010203 | L33: 검수완료
A34: c033 | B34: 우리 PCT 출원 요약서 영문본에 오류가 있습니다. | C34: PCT 국제출원문서 번역 | D34: =IFERROR(INDEX(분류체계!$D$2:$D$16,MATCH($C34,분류체계!$A$2:$A$16,0)),"") -> 정보활용본부 · IP정보가공실 | E34: 한영 기계번역(K2E-PAT) | F34: 지식재산 정보화 국제협력 | H34: PCT 요약서 영문 제작·검수는 WIPO사업팀이 맡습니다. | I34: 3 | J34: 지식재산정보 활용촉진 | K34: https://www.kipi.or.kr/EgovPageLink.do?link=/main/sub03/sub010402 | L34: 검수완료
A35: c034 | B35: 특허 공보 영문본을 대량으로 받고 싶습니다. | C35: 한영 기계번역(K2E-PAT) | D35: =IFERROR(INDEX(분류체계!$D$2:$D$16,MATCH($C35,분류체계!$A$2:$A$16,0)),"") -> 지능정보화센터 · 지능정보기술실 | E35: 특허정보활용서비스(KIPRISPlus) | F35: 데이터관리센터 | H35: K2E-PAT 한영 기계번역으로 맞춤형 대량 제공이 가능합니다. | I35: 2 | J35: 지식재산정보 활용촉진 | K35: https://www.kipi.or.kr/EgovPageLink.do?link=/main/sub03/sub010401 | L35: 검수완료
A36: c035 | B36: 받은 영문 데이터의 전문용어가 어색합니다. | C36: 한영 기계번역(K2E-PAT) | D36: =IFERROR(INDEX(분류체계!$D$2:$D$16,MATCH($C36,분류체계!$A$2:$A$16,0)),"") -> 지능정보화센터 · 지능정보기술실 | E36: 지식재산 정보화 R&D | F36: 데이터관리센터 | H36: 특허전문 MT엔진을 지속 트레이닝해 개선합니다. | I36: 2 | J36: 지식재산정보 활용촉진 | K36: https://www.kipi.or.kr/EgovPageLink.do?link=/main/sub03/sub010401 | L36: 검수완료
A37: c036 | B37: PCT 국제조사보고서 영문본이 필요합니다. | C37: PCT 국제출원문서 번역 | D37: =IFERROR(INDEX(분류체계!$D$2:$D$16,MATCH($C37,분류체계!$A$2:$A$16,0)),"") -> 정보활용본부 · IP정보가공실 | E37: 한국특허영문초록(KPA) | F37: 특허넷시스템 운영 | G37: 지식재산 정보화 국제협력 | H37: PCT 국제출원문서 번역 서비스 과정에 포함됩니다. | I37: 3 | J37: 지식재산정보 활용촉진 | K37: https://www.kipi.or.kr/EgovPageLink.do?link=/main/sub03/sub010402 | L37: 검수완료
A38: c037 | B38: 실용신안 공보도 영문본이 제공되나요? | C38: 한영 기계번역(K2E-PAT) | D38: =IFERROR(INDEX(분류체계!$D$2:$D$16,MATCH($C38,분류체계!$A$2:$A$16,0)),"") -> 지능정보화센터 · 지능정보기술실 | E38: 한국특허영문초록(KPA) | F38: 데이터관리센터 | H38: 특허·실용신안 공보를 영문으로 기계번역합니다. | I38: 2 | J38: 지식재산정보 활용촉진 | K38: https://www.kipi.or.kr/EgovPageLink.do?link=/main/sub03/sub010401 | L38: 검수완료
A39: c038 | B39: 영문본은 WIPO에 어떻게 전달되나요? | C39: PCT 국제출원문서 번역 | D39: =IFERROR(INDEX(분류체계!$D$2:$D$16,MATCH($C39,분류체계!$A$2:$A$16,0)),"") -> 정보활용본부 · IP정보가공실 | E39: 지식재산 정보화 국제협력 | F39: 특허넷시스템 운영 | H39: 번역 후 WIPO 국제공개 절차로 이어집니다. | I39: 3 | J39: 지식재산정보 활용촉진 | K39: https://www.kipi.or.kr/EgovPageLink.do?link=/main/sub03/sub010402 | L39: 검수완료
A40: c039 | B40: 우리 요구에 맞춰 영문화해 주실 수 있나요? | C40: 한영 기계번역(K2E-PAT) | D40: =IFERROR(INDEX(분류체계!$D$2:$D$16,MATCH($C40,분류체계!$A$2:$A$16,0)),"") -> 지능정보화센터 · 지능정보기술실 | E40: 특허고객 상담서비스 | F40: 특허넷시스템 운영 | H40: 고객 요청에 따라 번역물을 가공해 제공합니다. | I40: 1 | J40: 지식재산정보 활용촉진 | K40: https://www.kipi.or.kr/EgovPageLink.do?link=/main/sub03/sub010401 | L40: 검수완료
A41: c040 | B41: 영문 공보 데이터를 우리 시스템에 넣고 싶습니다. | C41: 한영 기계번역(K2E-PAT) | D41: =IFERROR(INDEX(분류체계!$D$2:$D$16,MATCH($C41,분류체계!$A$2:$A$16,0)),"") -> 지능정보화센터 · 지능정보기술실 | E41: 특허정보활용서비스(KIPRISPlus) | F41: 한국특허영문초록(KPA) | H41: 맞춤형 가공과 대량 데이터 제공이 가능합니다. | I41: 3 | J41: 지식재산정보 활용촉진 | K41: https://www.kipi.or.kr/EgovPageLink.do?link=/main/sub03/sub010401 | L41: 검수완료
A42: c041 | B42: 연도별 특허 출원 건수 통계를 보고 싶습니다. | C42: 지식재산 통계서비스 | D42: =IFERROR(INDEX(분류체계!$D$2:$D$16,MATCH($C42,분류체계!$A$2:$A$16,0)),"") -> (확인 불가 — 게임 제외) | E42: 데이터관리센터 | F42: 특허정보검색서비스(KIPRIS) | H42: 지식재산 통계정보를 생산·보급합니다. | I42: 1 | J42: 지식재산정보 활용촉진 | K42: 브로슈어 p.11-12 / 미확인: 지식재산 통계서비스가 현행 주요사업 메뉴에 없음 | L42: 보류
A43: c042 | B43: 특허 동향을 정리한 정기 간행물이 있나요? | C43: 지식재산 통계서비스 | D43: =IFERROR(INDEX(분류체계!$D$2:$D$16,MATCH($C43,분류체계!$A$2:$A$16,0)),"") -> (확인 불가 — 게임 제외) | E43: 지식재산 기술지원 | F43: 국제특허정보박람회(PATINEX) | H43: 통계로 보는 특허동향을 연 1회 발간합니다. | I43: 2 | J43: 지식재산정보 활용촉진 | K43: 브로슈어 p.11-12 / 미확인: 통계로 보는 특허동향 발간 여부 확인 불가 | L43: 보류
A44: c043 | B44: 지식재산 통계 FOCUS는 얼마나 자주 나오나요? | C44: 지식재산 통계서비스 | D44: =IFERROR(INDEX(분류체계!$D$2:$D$16,MATCH($C44,분류체계!$A$2:$A$16,0)),"") -> (확인 불가 — 게임 제외) | E44: 지식재산 기술지원 | F44: 데이터관리센터 | H44: 지식재산 통계 FOCUS는 연 2회 발간됩니다. | I44: 2 | J44: 지식재산정보 활용촉진 | K44: 브로슈어 p.11-12 / 미확인: 지식재산 통계 FOCUS 발간 주기 확인 불가 | L44: 보류
A45: c044 | B45: 통계를 웹에서 직접 조회할 수 있나요? | C45: 지식재산 통계서비스 | D45: =IFERROR(INDEX(분류체계!$D$2:$D$16,MATCH($C45,분류체계!$A$2:$A$16,0)),"") -> (확인 불가 — 게임 제외) | E45: 특허정보검색서비스(KIPRIS) | F45: 특허정보활용서비스(KIPRISPlus) | H45: 지식재산 통계 온라인 서비스(ipstat.kipi.or.kr)를 운영합니다. | I45: 1 | J45: 지식재산정보 활용촉진 | K45: 브로슈어 p.11-12 / 미확인: ipstat.kipi.or.kr 접속 불가(오류 페이지) | L45: 보류
...

Sheet 분류체계
A1: 정답 분류 | B1: 사업영역 | C1: 주요 업무 | D1: 표시 부서 (버튼 배지) | E1: 출처 (www.kipi.or.kr) | G1: 게임 노출
A2: 데이터관리센터 | B2: 지식재산정보 활용촉진 | C2: 데이터 품질관리(오류 판단·수정·패턴분석), IP5 등 해외 주요기관 데이터 입수, KIPRIS·KOMPASS DB 구축, 국내외 기관 원천데이터 제공, 국제표준 가공·배포 | D2: 분석플랫폼지원단 · 데이터관리실 | E2: /main/sub03/sub010201 | F2: 15 | G2: 노출
A3: 특허정보검색서비스(KIPRIS) | B3: 지식재산정보 활용촉진 | C3: 대국민 검색서비스 KIPRIS 운영. 반응형 웹, 국내외 통합검색, 행정이력·중간서류철, 마이폴더·검색식 메일링·공보발간 예고·추천검색식 | D3: 정보활용본부 · IP정보확산실 | E3: /main/sub03/sub0101 | F3: 15 | G3: 노출
A4: 특허문서전자화센터 | B4: 지식재산정보 활용촉진 | C4: 서면서류 스캐닝·전자화, 온라인 제출서류 명세서 전자화, 상표견본 키워드 입력, 심결문 비실명화, 전자화결과통지서 발송, 출원지원교육 | D4: 지능정보화센터 · 지능정보데이터실 | E4: /main/sub03/sub010202 | F4: 15 | G4: 노출
A5: 한국특허영문초록(KPA) | B5: 지식재산정보 활용촉진 | C5: 한국특허공보 영문요약서 제작(등록 1979.1~, 공개 1999.1~), FTP 국내외 보급, KIPRIS·Espacenet·Patentscope 검색 제공 | D5: 정보활용본부 · IP정보가공실 | E5: /main/sub03/sub010203 | F5: 15 | G5: 노출
A6: PCT 국제출원문서 번역 | B6: 지식재산정보 활용촉진 | C6: PCT 규칙 제48조3에 따라 WIPO에 제출된 한국어 국제출원문서(요약서·국제조사보고서·견해서)를 영문 번역해 국제공개를 지원 | D6: 정보활용본부 · IP정보가공실 | E6: /main/sub03/sub010402 (담당 표기는 구 조직명 국제협력팀 / 업무분장표 BB110: IP정보가공실 WIPO사업팀) | F6: 6 | G6: 노출
A7: 한영 기계번역(K2E-PAT) | B7: 지식재산정보 활용촉진 | C7: 시스트란 인터내셔널과 공동 개발한 한영 기계번역 엔진. 특허·실용신안 공보 기계번역물을 고객 요청에 따라 가공해 대량 제공, 번역엔진 지속 트레이닝 | D7: 지능정보화센터 · 지능정보기술실 | E7: /main/sub03/sub010401 (업무분장표 BB110: 지능정보기술실 지능화번역팀) | F7: 9 | G7: 노출
A8: 지식재산 통계서비스 | B8: 지식재산정보 활용촉진 | C8: [보류] 현행 주요사업 메뉴에 해당 항목 없음. ipstat.kipi.or.kr 접속 불가. 존속 여부 담당부서 확인 필요 — 신규 문항 미배정 | D8: (확인 불가 — 게임 제외) | E8: 현행 사이트에서 미확인 | F8: 7 | G8: 제외
A9: IP정보통합센터 | B9: 지식재산정보산업 육성/지원 | C9: 민간 클라우드 기반 IP정보시스템 통합 운영(2026.1 기준 7개 기관 40개 시스템), 공동활용자원 관리, 침해사고 대응, 보안관제, 취약점 점검 | D9: 정보시스템본부 · IP시스템기반실 | E9: /main/sub03/sub030200 | F9: 15 | G9: 노출
A10: 특허정보활용서비스(KIPRISPlus) | B10: 지식재산정보산업 육성/지원 | C10: IP정보 개방·유통 플랫폼. Bulk Data·Open API·LOD 제공, IP데이터 기프트 제도, 창업 경진대회, IP정보 스타트업 해외진출 지원 | D10: 정보활용본부 · IP정보확산실 | E10: /main/sub03/sub0301 | F10: 15 | G10: 노출
A11: 국제특허정보박람회(PATINEX) | B11: 지식재산정보산업 육성/지원 | C11: 2005년부터 개최. 지식재산처·한국특허정보원 공동 주최. 참가자 700여명, 전시업체 20여개. 전시·컨퍼런스·부대행사 구성 | D11: 정보활용본부 · IP정보확산실 | E11: /main/sub03/sub0303 | F11: 15 | G11: 노출
A12: 지식재산 정보화 R&D | B12: 지식재산정보산업 육성/지원 | C12: 지능정보 지식베이스(특허기술용어사전, 조성/물성, 기계번역 코퍼스), 사전학습 언어모델, 특징 추출·기술분류·유사특허검색 모델 연구 | D12: 지능정보화센터 · 지능정보전략실 | E12: /main/sub03/sub0304 | F12: 14 | G12: 노출
A13: 특허넷시스템 운영 | B13: 특허행정 정보화 및 업무지원 | C13: 특허넷(KIPOnet) 응용·기반시스템 24시간 365일 운영. 재난복구·이중화 훈련, 보안관제, 법·제도 반영, 지식재산처 정보화 품질관리·전자정부 대응 | D13: 정보시스템본부 · IP시스템기반실 | E13: /main/sub03/sub0201 | F13: 15 | G13: 노출
... A16: 지식재산 기술지원 | B16: 지식재산 기술지원 | C16: 보유 기술·지식재산권·연구논문·학습데이터의 기술이전(공고→신청→계약조건 협상→계약체결→기술지도), 보유기술목록·기술홍보자료·최신기술동향 공개 | D16: 경영관리본부 · 전략기획실 | E16: /main/sub03/sub0401~0404 (담당 표기 지능정보전략실 / 업무분장표 BB110: 전략기획실 혁신성과팀) | F16: 14 | G16: 노출
A17: 합계 | E17: =SUM(E2:E15) -> 0 | F17: =SUM(F2:F16) -> 200 | G17: =SUMIF(G2:G16,"노출",F2:F16) -> 193

Sheet 난이도분포
A1: 난이도 | B1: 설명 | C1: 문항 수 | D1: 비율 | E1: 권장 비율
A2: 1 | B2: 명확 — 업무명이 민원 문장에 거의 드러남 | C2: =COUNTIF(문제은행!$I$2:$I$201,1) -> 49 | D2: =C2/$C$5 -> 0.245 | E2: 0.4
A3: 2 | B3: 보통 — 유사 사업과 혼동 가능 | C3: =COUNTIF(문제은행!$I$2:$I$201,2) -> 103 | D3: =C3/$C$5 -> 0.515 | E3: 0.4
A4: 3 | B4: 어려움 — 세부 업무 지식 필요 | C4: =COUNTIF(문제은행!$I$2:$I$201,3) -> 48 | D4: =C4/$C$5 -> 0.24 | E4: 0.2
A5: 합계 | C5: =SUM(C2:C4) -> 200 | D5: =SUM(D2:D4) -> 1 | E5: =SUM(E2:E4) -> 1

Sheet 작성가이드
A1: 민원 연결의 神 — 문제 은행 작성 가이드
A3: ■ 이 파일의 용도
A4: 게임에서 민원인이 말하는 문장과 정답 부서를 정의하는 원본 데이터입니다.
A5: frontend/src/data/complaints.ts 로 변환해 게임에 반영합니다.
A7: ■ 채워야 할 칸 (노란색)
A8: 문제은행 시트의 행을 아래로 계속 추가하시면 됩니다.
A9: 정답 분류 / 오답후보 / 난이도 / 검수상태는 드롭다운으로 선택합니다.
A11: ■ 작성 규칙
A12: 민원 내용 | B12: 민원인이 실제로 할 법한 말투. 40자 이내. 부서명을 그대로 쓰지 말 것
A13: 정답 분류 | B13: 분류체계 시트의 14개 중 하나. 새 분류가 필요하면 먼저 분류체계에 추가
A14: 오답후보 | B14: 헷갈리기 쉬운 분류를 1~3개. 비워두면 무작위로 채워짐
A15: 해설 | B15: 왜 그 분류인지 한 줄. 45자 이내. 오답 시 화면에 그대로 표시됨
A16: 난이도 | B16: 1=명확 / 2=혼동 가능 / 3=세부 지식 필요. 목표 비율 4:4:2
A17: 출처 | B17: 근거 자료. 예: 브로슈어 p.07-08, kipi.or.kr 주요사업, 부서 담당자 확인
A18: 검수상태 | B18: 해당 부서 담당자 확인을 받으면 검수완료로 변경
A20: ■ 예시 (이 행 형식 그대로 작성)
A21: 민원 내용 | B21: 검색된 특허의 출원인 이름이 실제와 다르게 나옵니다.
A22: 정답 분류 | B22: 데이터관리센터
A23: 오답후보1 | B23: 특허정보검색서비스(KIPRIS)
A24: 해설 | B24: 특허데이터 오류 판단·수정은 데이터관리센터가 담당합니다.
A25: 난이도 | B25: 1
A26: 출처 | B26: 브로슈어 p.07-08
A28: ■ 목표 물량
A29: 1판 180초에 50~60문항이 소비되고, 1인 3회 플레이 시 150~180문항이 필요합니다.
A30: 중복 체감을 막으려면 최소 200문항을 확보해야 합니다.
A31: 현재 100문항이므로 100문항이 더 필요합니다.
A32: 부서별 담당자에게 5문항씩 요청해 분산 수집하는 방식을 권장합니다.
A34: ■ 출처 표기 원칙
A35: 브로슈어 = 첨부된 KIPI 국영문 브로슈어 (발행일 2020-10-15). 쪽수는 인쇄면 번호.
A36: kipi.or.kr 주요사업 = 홈페이지 주요사업 메뉴 구조.
A37: 주의: 브로슈어는 2020년 발행본입니다. 조직 개편이나 사업 변경 사항은
A38: 반드시 현행 조직도와 대조해 검수하십시오.

Sheet 변경요약
A1: ■ 조사 범위
A2: 조사일 | B2: 2026-08-13. www.kipi.or.kr 주요사업 하위 14개 페이지 + 사이트맵 + 조직안내 전문 열람
A3: 메뉴 구조 | B3: 4개 사업영역 / 14개 사업. 기존 분류체계와 구조 일치 — 분류 신설·폐지 없음
A5: ■ 전사적 변경
A6: 기관명 | B6: 특허청 → 지식재산처. 사이트 전 페이지에서 확인. 해설 문구 반영 완료(c004, c019)
A8: ■ 정답 오류 수정 (2건)
A9: c070 | B9: 지식재산 정보화 R&D → 특허고객 상담서비스. 챗봇상담은 상담센터가 실제 운영 중인 서비스이며 현행 R&D 과제 목록에 자동 특허상담 없음
A10: c078 | B10: 특허넷시스템 운영 → 특허고객 상담서비스. 전자출원SW 오류는 PC원격상담 서비스 소관으로 명시됨
A12: ■ 해설 현행화 (21건)
A13: 대상 | B13: c002 c004 c011 c013 c016 c019 c020 c021 c030 c035 c039 c048 c050 c051 c052 c053 c061 c067 c069 c071 c072
A14: 주요 사유 | B14: ① 39개 기관 → IP5 등 해외 주요기관 ② 나의 관심특허 → 검색식 메일링 ③ 찾아가는 특허서비스 → KIPRIS 연계
B15: ④ IP정보통합센터 서술을 민간 클라우드 기준으로 전면 교체 ⑤ Bulk/Open API의 실시간 표현 교정
A17: ■ 보류 (14건) — 사이트에서 확인 불가
A18: c041~c047 | B18: 지식재산 통계서비스. 현행 주요사업 메뉴에 항목 없고 ipstat.kipi.or.kr 접속 불가. 담당부서 확인 필요
A19: c017 | B19: KIPRIS 비특허문헌(NPL) 검색 기능 언급 없음
A20: c058 | B20: Open API 인증키 발급 절차가 사업 소개 페이지에 없음
A21: c068 | B21: 현행 R&D 과제 목록에 도면 유사 추출 없음
A22: c086 c088 | B22: 외국어 상담·상담 이력 조회 여부 상담 페이지에 명시 없음
A23: c091 c092 | B23: UAE·ARIPO 및 13개국 수치가 현행 국제협력 페이지에 없음
A25: ■ 신규 문항 (c101~c200)
A26: 배분 | B26: 통계서비스를 제외한 13개 분류에 배정. 분류당 14~15문항으로 균등화
A27: 출처 | B27: 전 문항 직접 열람한 페이지 URL 기재. 추정 서술 없음
A29: ■ 난이도
A30: 결과 | B30: 51 : 103 : 46 (25.5% : 51.5% : 23%). 목표 40:40:20 미달
A31: 사유 | B31: 기존 100문항이 25:46:29여서 200문항에서 목표 달성에 필요한 신규 배분은 55:34:11.
B32: 난이도 1은 업무 성격이 문장에 드러나야 하는데, 이는 작성 규칙 ①(민원 문장에 정답 금지)과 상충.
A33: 권장 | B33: 목표를 25:50:25로 조정하거나, 난이도 1을 늘리려면 규칙 ①의 예외 범위를 먼저 정할 것
A35: ■ 남은 과제 (이번 작업 범위 밖)
A36: 정답 노출 | B36: 기존 문항 22건이 민원 문장에 정답 분류명을 그대로 포함(번역 7/8, 통계 6/7, KPA 4/6).
B37: 업무 지식이 아닌 글자 매칭 문제가 됨. 문장 재작성 권장 — 정답 자체는 맞으므로 검수완료 처리
A38: 오답 편중 | B38: 오답후보 노출이 데이터관리센터·특허넷에 집중. 신규 문항에서 완화했으나 추가 조정 여지 있음
A39: 통계서비스 | B39: 존속 여부에 따라 7문항을 살릴지 폐기할지 결정 필요. 폐기 시 분류 13개로 축소
A41: ■ 2차 수정 (분류 표기 체계 · 정답 노출)
A42: 표기 체계 | B42: C안 채택 — 버튼을 「본부·실 배지 + 서비스명」 2단으로 표시.
B43: 정답 분류 값은 키로 유지(오답후보 참조 안정성). 표시 부서는 분류체계 D열에서 수식 조회 — 문제은행 D열 직접 수정 금지
A44: 부서 확정 | B44: 국제협력팀은 IP정보확산실 소속으로 확인. 실 단위로 배지 통일
A45: IP정보확산실 | B45: KIPRIS·KIPRISPlus·PATINEX·국제협력·번역 5개 사업 담당. 배지 5회 반복되므로 배지는 작게, 서비스명을 크게
A47: ■ 정답 노출 수정 (39건)
A48: 결과 | B48: 49건 → 6건. 잔여 6건은 전부 통계서비스(보류·게임 제외)이므로 실질 0건
A49: 수정 원칙 | B49: 민원인이 겪는 상황으로 환원. 정답 분류·해설·오답후보·난이도는 손대지 않음
...
